Traceback (most recent call last):
  File "C:\Users\Admin\Desktop\Chernyshev\Sob\NewsExtractor\venv\lib\site-packages\urllib3\connection.py", line 174, in _new_conn
    conn = connection.create_connection(
  File "C:\Users\Admin\Desktop\Chernyshev\Sob\NewsExtractor\venv\lib\site-packages\urllib3\util\connection.py", line 95, in create_connection
    raise err
  File "C:\Users\Admin\Desktop\Chernyshev\Sob\NewsExtractor\venv\lib\site-packages\urllib3\util\connection.py", line 85, in create_connection
    sock.connect(sa)
ConnectionRefusedError: [WinError 10061] Подключение не установлено, т.к. конечный компьютер отверг запрос на подключение

During handling of the above exception, another exception occurred:

Traceback (most recent call last):
  File "C:\Users\Admin\Desktop\Chernyshev\Sob\NewsExtractor\venv\lib\site-packages\urllib3\connectionpool.py", line 716, in urlopen
    httplib_response = self._make_request(
  File "C:\Users\Admin\Desktop\Chernyshev\Sob\NewsExtractor\venv\lib\site-packages\urllib3\connectionpool.py", line 416, in _make_request
    conn.request(method, url, **httplib_request_kw)
  File "C:\Users\Admin\Desktop\Chernyshev\Sob\NewsExtractor\venv\lib\site-packages\urllib3\connection.py", line 244, in request
    super(HTTPConnection, self).request(method, url, body=body, headers=headers)
  File "C:\Users\Admin\AppData\Local\Programs\Python\Python39\lib\http\client.py", line 1255, in request
    self._send_request(method, url, body, headers, encode_chunked)
  File "C:\Users\Admin\AppData\Local\Programs\Python\Python39\lib\http\client.py", line 1301, in _send_request
    self.endheaders(body, encode_chunked=encode_chunked)
  File "C:\Users\Admin\AppData\Local\Programs\Python\Python39\lib\http\client.py", line 1250, in endheaders
    self._send_output(message_body, encode_chunked=encode_chunked)
  File "C:\Users\Admin\AppData\Local\Programs\Python\Python39\lib\http\client.py", line 1010, in _send_output
    self.send(msg)
  File "C:\Users\Admin\AppData\Local\Programs\Python\Python39\lib\http\client.py", line 950, in send
    self.connect()
  File "C:\Users\Admin\Desktop\Chernyshev\Sob\NewsExtractor\venv\lib\site-packages\urllib3\connection.py", line 205, in connect
    conn = self._new_conn()
  File "C:\Users\Admin\Desktop\Chernyshev\Sob\NewsExtractor\venv\lib\site-packages\urllib3\connection.py", line 186, in _new_conn
    raise NewConnectionError(
urllib3.exceptions.NewConnectionError: <urllib3.connection.HTTPConnection object at 0x000001A0D62EAB80>: Failed to establish a new connection: [WinError 10061] Подключение не установлено, т.к. конечный компьютер отверг запрос на подключение

During handling of the above exception, another exception occurred:

Traceback (most recent call last):
  File "C:\Users\Admin\Desktop\Chernyshev\Sob\NewsExtractor\venv\lib\site-packages\requests\adapters.py", line 667, in send
    resp = conn.urlopen(
  File "C:\Users\Admin\Desktop\Chernyshev\Sob\NewsExtractor\venv\lib\site-packages\urllib3\connectionpool.py", line 802, in urlopen
    retries = retries.increment(
  File "C:\Users\Admin\Desktop\Chernyshev\Sob\NewsExtractor\venv\lib\site-packages\urllib3\util\retry.py", line 594, in increment
    raise MaxRetryError(_pool, url, error or ResponseError(cause))
urllib3.exceptions.MaxRetryError: HTTPConnectionPool(host='localhost', port=11434): Max retries exceeded with url: /api/chat (Caused by NewConnectionError('<urllib3.connection.HTTPConnection object at 0x000001A0D62EAB80>: Failed to establish a new connection: [WinError 10061] Подключение не установлено, т.к. конечный компьютер отверг запрос на подключение'))      

During handling of the above exception, another exception occurred:

Traceback (most recent call last):
  File "C:\Users\Admin\Desktop\Chernyshev\Sob\NewsExtractor\test.py", line 21, in <module>
    result = smart_scraper_graph.run()
  File "C:\Users\Admin\Desktop\Chernyshev\Sob\NewsExtractor\venv\lib\site-packages\scrapegraphai\graphs\smart_scraper_graph.py", line 114, in run
    self.final_state, self.execution_info = self.graph.execute(inputs)
  File "C:\Users\Admin\Desktop\Chernyshev\Sob\NewsExtractor\venv\lib\site-packages\scrapegraphai\graphs\base_graph.py", line 263, in execute
    return self._execute_standard(initial_state)
  File "C:\Users\Admin\Desktop\Chernyshev\Sob\NewsExtractor\venv\lib\site-packages\scrapegraphai\graphs\base_graph.py", line 184, in _execute_standard
    raise e
  File "C:\Users\Admin\Desktop\Chernyshev\Sob\NewsExtractor\venv\lib\site-packages\scrapegraphai\graphs\base_graph.py", line 168, in _execute_standard
    result = current_node.execute(state)
  File "C:\Users\Admin\Desktop\Chernyshev\Sob\NewsExtractor\venv\lib\site-packages\scrapegraphai\nodes\generate_answer_node.py", line 134, in execute
    answer = chain.invoke({"question": user_prompt})
  File "C:\Users\Admin\Desktop\Chernyshev\Sob\NewsExtractor\venv\lib\site-packages\langchain_core\runnables\base.py", line 3034, in invoke
    input = context.run(step.invoke, input, config)
  File "C:\Users\Admin\Desktop\Chernyshev\Sob\NewsExtractor\venv\lib\site-packages\langchain_core\language_models\chat_models.py", line 370, in invoke
    self.generate_prompt(
  File "C:\Users\Admin\Desktop\Chernyshev\Sob\NewsExtractor\venv\lib\site-packages\langchain_core\language_models\chat_models.py", line 947, in generate_prompt
    return self.generate(prompt_messages, stop=stop, callbacks=callbacks, **kwargs)
  File "C:\Users\Admin\Desktop\Chernyshev\Sob\NewsExtractor\venv\lib\site-packages\langchain_core\language_models\chat_models.py", line 766, in generate
    self._generate_with_cache(
  File "C:\Users\Admin\Desktop\Chernyshev\Sob\NewsExtractor\venv\lib\site-packages\langchain_core\language_models\chat_models.py", line 1012, in _generate_with_cache
    result = self._generate(
  File "C:\Users\Admin\Desktop\Chernyshev\Sob\NewsExtractor\venv\lib\site-packages\langchain_community\chat_models\ollama.py", line 291, in _generate
    final_chunk = self._chat_stream_with_aggregation(
  File "C:\Users\Admin\Desktop\Chernyshev\Sob\NewsExtractor\venv\lib\site-packages\langchain_community\chat_models\ollama.py", line 222, in _chat_stream_with_aggregation
    for stream_resp in self._create_chat_stream(messages, stop, **kwargs):
  File "C:\Users\Admin\Desktop\Chernyshev\Sob\NewsExtractor\venv\lib\site-packages\langchain_community\chat_models\ollama.py", line 194, in _create_chat_stream
    yield from self._create_stream(
  File "C:\Users\Admin\Desktop\Chernyshev\Sob\NewsExtractor\venv\lib\site-packages\langchain_community\llms\ollama.py", line 252, in _create_stream
    response = requests.post(
  File "C:\Users\Admin\Desktop\Chernyshev\Sob\NewsExtractor\venv\lib\site-packages\requests\api.py", line 115, in post
    return request("post", url, data=data, json=json, **kwargs)
  File "C:\Users\Admin\Desktop\Chernyshev\Sob\NewsExtractor\venv\lib\site-packages\requests\api.py", line 59, in request
    return session.request(method=method, url=url, **kwargs)
  File "C:\Users\Admin\Desktop\Chernyshev\Sob\NewsExtractor\venv\lib\site-packages\requests\sessions.py", line 589, in request
    resp = self.send(prep, **send_kwargs)
  File "C:\Users\Admin\Desktop\Chernyshev\Sob\NewsExtractor\venv\lib\site-packages\requests\sessions.py", line 703, in send
    r = adapter.send(request, **kwargs)
  File "C:\Users\Admin\Desktop\Chernyshev\Sob\NewsExtractor\venv\lib\site-packages\requests\adapters.py", line 700, in send
    raise ConnectionError(e, request=request)
requests.exceptions.ConnectionError: HTTPConnectionPool(host='localhost', port=11434): Max retries exceeded with url: /api/chat (Caused by NewConnectionError('<urllib3.connection.HTTPConnection object at 0x000001A0D62EAB80>: Failed to establish a new connection: [WinError 10061] Подключение не установлено, т.к. конечный компьютер отверг запрос на подключение')) 